Workbook

Sheet N32
A1: Datos de entrada
A2: Alfa -grad | B2: -0.66655153 | C2: INPUT
A3: Alfa - rad | B3: =(B2*PI())/180 -> -0.011633519 | E3: NOTA IMPORTANTE
A4: Cuerda | B4: 1 | C4: INPUT | E4: SI SE MODIFICAN EL NÚMERO TOTAL DE PANELES HABRÁ QUE AMPLIAR O REDUCIR LAS COLUMNAS DE DATOS - PREFERIBLEMENTE AMPLIARLAS PARA MAYOR PRECISIÓN
A5: Numero paneles | B5: 32 | C5: INPUT | E5: SI SE MODIFICAN LOS VALORES DE Xf ó Ca HABRÁ QUE MODIFICAR LAS COLUMNAS DE COORDENADAS PARA LOS DATOS DE LA LM TANTO LOS PC COMO NODOS.
A6: L panel | B6: =B4/B5 -> 0.03125
A7: Ca | B7: 0.3 | C7: INPUT
A8: Xf | B8: 0.2 | C8: INPUT
A9: delta e - grad | B9: 0 | C9: INPUT
A10: delta e - rad | B10: =(B9*PI())/180 -> 0
A11: f | B11: 0.04 | C11: INPUT
A12: NO TOCAR NINGÚN VALOR DE AQUÍ PARA ABAJO | BC12: Con -1 sale bastante preciso | BF12: MATRIZ A
CM13: Matriz A invertida
A14: MODIFICAR INPUTS, RESTO CAMBIA SOLO | W14: 1 | X14: 2 | Y14: 3 | Z14: 4 | AA14: 5 | AB14: 6 | AC14: 7 | AD14: 8 | AE14: 9 | AF14: 10 | AG14: 11 | AH14: 12 | AI14: 13 | AJ14: 14 | AK14: 15 | AL14: 16 | AM14: 17 | AN14: 18 | AO14: 19 | AP14: 20 | AQ14: 21 | AR14: 22 | AS14: 23 | AT14: 24 | AU14: 25 | AV14: 26 | AW14: 27 | AX14: 28 | AY14: 29 | AZ14: 30 | BA14: 31 | BB14: 32 | BC14: ????????? | BF14: 1 | BG14: 2 | BH14: 3 | BI14: 4 | BJ14: 5 | BK14: 6 | BL14: 7 | BM14: 8 | BN14: 9 | BO14: 10 | BP14: 11 | BQ14: 12 | BR14: 13 | BS14: 14 | BT14: 15 | BU14: 16 | BV14: 17 | BW14: 18 | BX14: 19 | BY14: 20 | BZ14: 21 | CA14: 22 | CB14: 23 | CC14: 24 | CD14: 25 | CE14: 26 | CF14: 27 | CG14: 28 | CH14: 29 | CI14: 30 | CJ14: 31 | CK14: 32
V15: lj | W15: r(i,j) | X15: r(i,j) | Y15: r(i,j) | Z15: r(i,j) | AA15: r(i,j) | AB15: r(i,j) | AC15: r(i,j) | AD15: r(i,j) | AE15: r(i,j) | AF15: r(i,j) | AG15: r(i,j) | AH15: r(i,j) | AI15: r(i,j) | AJ15: r(i,j) | AK15: r(i,j) | AL15: r(i,j) | AM15: r(i,j) | AN15: r(i,j) | AO15: r(i,j) | AP15: r(i,j) | AQ15: r(i,j) | AR15: r(i,j) | AS15: r(i,j) | AT15: r(i,j) | AU15: r(i,j) | AV15: r(i,j) | AW15: r(i,j) | AX15: r(i,j) | AY15: r(i,j) | AZ15: r(i,j) | BA15: r(i,j) | BB15: r(i,j) | CM15: 1 | CN15: 2 | CO15: 3 | CP15: 4 | CQ15: 5 | CR15: 6 | CS15: 7 | CT15: 8 | CU15: 9 | CV15: 10 | CW15: 11 | CX15: 12 | CY15: 13 | CZ15: 14 | DA15: 15 | DB15: 16 | DC15: 17 | DD15: 18 | DE15: 19 | DF15: 20 | DG15: 21 | DH15: 22 | DI15: 23 | DJ15: 24 | DK15: 25 | DL15: 26 | DM15: 27 | DN15: 28 | DO15: 29 | DP15: 30 | DQ15: 31 | DR15: 32
B16: Numero de paneles | E16: xNodo_sinAlerón | F16: zNodo_sinAlerón | G16: zNodo_conAlerón | H16: xci_sinAlerón | I16: xci_conAlerón | J16: zci_sinAlerón | K16: zci_conAlerón | L16: (dz/dx)i_sinAlerón | M16: (dz/dx)i_conAlerón | P16: bi_sinAlerón | Q16: bi_conAlerón | V16: =E18-E17 -> 0.03125 | W16: =H17-E17 -> 0.015625 | X16: =H17-E18 -> -0.015625 | Y16: =H17-E19 -> -0.046875 | Z16: =H17-E20 -> -0.078125 | AA16: =H17-E21 -> -0.109375 | AB16: =H17-E22 -> -0.140625 | AC16: =H17-E23 -> -0.171875 | AD16: =H17-E24 -> -0.203125 | AE16: =H17-E25 -> -0.234375 | AF16: =H17-E26 -> -0.265625 | AG16: =H17-E27 -> -0.296875 | AH16: =H17-E28 -> -0.328125 | AI16: =H17-E29 -> -0.359375 | AJ16: =H17-E30 -> -0.390625 | AK16: =H17-E31 -> -0.421875 | AL16: =H17-E32 -> -0.453125 | AM16: =H17-E33 -> -0.484375 | AN16: =H17-E34 -> -0.515625 | AO16: =H17-E35 -> -0.546875 | AP16: =H17-E36 -> -0.578125 | AQ16: =H17-E37 -> -0.609375 | AR16: =H17-E38 -> -0.640625 | AS16: =H17-E39 -> -0.671875 | AT16: =H17-E40 -> -0.703125 | AU16: =H17-E41 -> -0.734375 | AV16: =H17-E42 -> -0.765625 | AW16: =H17-E43 -> -0.796875 | AX16: =H17-E44 -> -0.828125 | AY16: =H17-E45 -> -0.859375 | AZ16: =H17-E46 -> -0.890625 | BA16: =H17-E47 -> -0.921875 | BB16: =H17-E48 -> -0.953125 | BC16: =H17-$E$49 -> -0.984375 | BE16: 1 | BF16: =BZ82+AO82 -> -1 | BG16: =CA82+AP82 -> 1.6479184 | BH16: =CB82+AQ82 -> 0.72775792 | BI16: =CC82+AR82 -> 0.41141439 | BJ16: =CD82+AS82 -> 0.28973434 | BK16: =CE82+AT82 -> 0.22408833 | BL16: =CF82+AU82 -> 0.18283342 | BM16: =CG82+AV82 -> 0.15445886 | ... CK16: =DE82+BT82 -> 0.032792762 | CL16: 1 | CM16: {=MINVERSE(BF16:CK47)} -> -0.6329062 | CN16: -0.2747758 | CO16: -0.22347995 | CP16: -0.19052901 | CQ16: -0.17044941 | CR16: -0.15664807 | CS16: -0.1466188 | CT16: -0.13905955 | CU16: -0.13323431 | CV16: -0.12869393 | CW16: -0.12514966 | CX16: -0.12240906 | CY16: -0.12034133 | CZ16: -0.11885734 | DA16: -0.11789791 | DB16: -0.11742681 | DC16: -0.11742681 | DD16: -0.11789791 | DE16: -0.11885734 | DF16: -0.12034133 | DG16: -0.12240906 | DH16: -0.12514966 | DI16: -0.12869393 | DJ16: -0.13323431 | DK16: -0.13905955 | DL16: -0.1466188 | DM16: -0.15664807 | DN16: -0.17044941 | DO16: -0.19052901 | DP16: -0.22347995 | DQ16: -0.2747758 | DR16: -0.6329062
B17: 1 | E17: 0 | F17: =($B$11/$B$8^2)*(2*E17*$B$8-E17^2) -> 0 | G17: =($B$11/$B$8^2)*(2*E17*$B$8-E17^2) -> 0 | H17: =(E18+E17)/2 -> 0.015625 | I17: =(E18+E17)/2 -> 0.015625 | J17: =(F18+F17)/2 -> 0.0057617187 | K17: =(G18+G17)/2 -> 0.0057617187 | L17: =((2*$B$11)/$B$8)-(2*$B$11*H17)/$B$8^2 -> 0.36875 | M17: =((2*$B$11)/$B$8)-(2*$B$11*H17)/$B$8^2 -> 0.36875 | O17: 1 | P17: =-2*PI()*($B$3-L17) -> 2.3900201 | Q17: =-2*PI()*($B$3-M17) -> 2.3900201 | V17: =E19-E18 -> 0.03125 | W17: =H18-E17 -> 0.046875 | X17: =H18-E18 -> 0.015625 | Y17: =H18-E19 -> -0.015625 | Z17: =H18-E20 -> -0.046875 | AA17: =H18-E21 -> -0.078125 | AB17: =H18-E22 -> -0.109375 | AC17: =H18-E23 -> -0.140625 | AD17: =H18-E24 -> -0.171875 | AE17: =H18-E25 -> -0.203125 | AF17: =H18-E26 -> -0.234375 | AG17: =H18-E27 -> -0.265625 | AH17: =H18-E28 -> -0.296875 | AI17: =H18-E29 -> -0.328125 | AJ17: =H18-E30 -> -0.359375 | AK17: =H18-E31 -> -0.390625 | AL17: =H18-E32 -> -0.421875 | AM17: =H18-E33 -> -0.453125 | AN17: =H18-E34 -> -0.484375 | AO17: =H18-E35 -> -0.515625 | AP17: =H18-E36 -> -0.546875 | AQ17: =H18-E37 -> -0.578125 | AR17: =H18-E38 -> -0.609375 | AS17: =H18-E39 -> -0.640625 | AT17: =H18-E40 -> -0.671875 | AU17: =H18-E41 -> -0.703125 | AV17: =H18-E42 -> -0.734375 | AW17: =H18-E43 -> -0.765625 | AX17: =H18-E44 -> -0.796875 | AY17: =H18-E45 -> -0.828125 | AZ17: =H18-E46 -> -0.859375 | BA17: =H18-E47 -> -0.890625 | BB17: =H18-E48 -> -0.921875 | BC17: =H18-$E$49 -> -0.953125 | BE17: 2 | BF17: =BZ83+AO83 -> -0.45069386 | BG17: =CA83+AP83 -> -1.6479184 | BH17: =CB83+AQ83 -> 1.6479184 | BI17: =CC83+AR83 -> 0.72775792 | BJ17: =CD83+AS83 -> 0.41141439 | BK17: =CE83+AT83 -> 0.28973434 | BL17: =CF83+AU83 -> 0.22408833 | BM17: =CG83+AV83 -> 0.18283342 | ... CK17: =DE83+BT83 -> 0.0339048 | CL17: 2 | CM17: 0.20578151 | CN17: -0.2828823 | CO17: -0.089040705 | CP17: -0.069638042 | CQ17: -0.056835008 | CR17: -0.049559022 | CS17: -0.044749668 | CT17: -0.041357677 | CU17: -0.038857685 | CV17: -0.036963866 | CW17: -0.03550702 | CX17: -0.034381063 | CY17: -0.033516757 | CZ17: -0.03286781 | DA17: -0.032403116 | DB17: -0.032102248 | DC17: -0.031952828 | DD17: -0.031949074 | DE17: -0.032091169 | DF17: -0.03238531 | DG17: -0.03284446 | DH17: -0.033489994 | DI17: -0.034354642 | DJ17: -0.03548762 | DK17: -0.036963681 | DL17: -0.038899884 | DM17: -0.041488776 | DN17: -0.04507169 | DO17: -0.050306375 | DP17: -0.058924458 | DQ17: -0.072362504 | DR17: -0.1664407
B18: 2 | E18: =$B$6*B17 -> 0.03125 | F18: =($B$11/$B$8^2)*(2*E18*$B$8-E18^2) -> 0.011523437 | G18: =($B$11/$B$8^2)*(2*E18*$B$8-E18^2) -> 0.011523437 | H18: =(E19+E18)/2 -> 0.046875 | I18: =(E19+E18)/2 -> 0.046875 | J18: =(F19+F18)/2 -> 0.016308594 | K18: =(G19+G18)/2 -> 0.016308594 | L18: =((2*$B$11)/$B$8)-(2*$B$11*H18)/$B$8^2 -> 0.30625 | M18: =((2*$B$11)/$B$8)-(2*$B$11*H18)/$B$8^2 -> 0.30625 | O18: 2 | P18: =-2*PI()*($B$3-L18) -> 1.9973211 | Q18: =-2*PI()*($B$3-M18) -> 1.9973211 | V18: =E20-E19 -> 0.03125 | W18: =H19-E17 -> 0.078125 | X18: =H19-E18 -> 0.046875 | Y18: =H19-E19 -> 0.015625 | Z18: =H19-E20 -> -0.015625 | AA18: =H19-E21 -> -0.046875 | AB18: =H19-E22 -> -0.078125 | AC18: =H19-E23 -> -0.109375 | AD18: =H19-E24 -> -0.140625 | AE18: =H19-E25 -> -0.171875 | AF18: =H19-E26 -> -0.203125 | AG18: =H19-E27 -> -0.234375 | AH18: =H19-E28 -> -0.265625 | AI18: =H19-E29 -> -0.296875 | AJ18: =H19-E30 -> -0.328125 | AK18: =H19-E31 -> -0.359375 | AL18: =H19-E32 -> -0.390625 | AM18: =H19-E33 -> -0.421875 | AN18: =H19-E34 -> -0.453125 | AO18: =H19-E35 -> -0.484375 | AP18: =H19-E36 -> -0.515625 | AQ18: =H19-E37 -> -0.546875 | AR18: =H19-E38 -> -0.578125 | AS18: =H19-E39 -> -0.609375 | AT18: =H19-E40 -> -0.640625 | AU18: =H19-E41 -> -0.671875 | AV18: =H19-E42 -> -0.703125 | AW18: =H19-E43 -> -0.734375 | AX18: =H19-E44 -> -0.765625 | AY18: =H19-E45 -> -0.796875 | AZ18: =H19-E46 -> -0.828125 | BA18: =H19-E47 -> -0.859375 | BB18: =H19-E48 -> -0.890625 | BC18: =H19-$E$49 -> -0.921875 | BE18: 3 | BF18: =BZ84+AO84 -> -0.23376156 | BG18: =CA84+AP84 -> -0.72775792 | BH18: =CB84+AQ84 -> -1.6479184 | BI18: =CC84+AR84 -> 1.6479184 | BJ18: =CD84+AS84 -> 0.72775792 | BK18: =CE84+AT84 -> 0.41141439 | BL18: =CF84+AU84 -> 0.28973434 | BM18: =CG84+AV84 -> 0.22408833 | ... CK18: =DE84+BT84 -> 0.035094923 | CL18: 3 | CM18: 0.02109002 | CN18: 0.2197784 | CO18: -0.27337827 | CP18: -0.081049431 | CQ18: -0.062588428 | CR18: -0.050418757 | CS18: -0.043602734 | CT18: -0.039143076 | CU18: -0.036025465 | CV18: -0.033745571 | CW18: -0.032031084 | CX18: -0.030721939 | CY18: -0.029718487 | CZ18: -0.028956182 | DA18: -0.028392285 | DB18: -0.027998477 | DC18: -0.027756628 | DD18: -0.02765638 | DE18: -0.027693888 | DF18: -0.027871401 | DG18: -0.0281976 | DH18: -0.028688774 | DI18: -0.029371176 | DJ18: -0.030285252 | DK18: -0.031493208 | DL18: -0.033093115 | DM18: -0.035246878 | DN18: -0.038242084 | DO18: -0.042633478 | DP18: -0.049882481 | DQ18: -0.061200819 | DR18: -0.14061239
B19: 3 | E19: =$B$6*B18 -> 0.0625 | F19: =($B$11/$B$8^2)*(2*E19*$B$8-E19^2) -> 0.02109375 | G19: =($B$11/$B$8^2)*(2*E19*$B$8-E19^2) -> 0.02109375 | H19: =(E20+E19)/2 -> 0.078125 | I19: =(E20+E19)/2 -> 0.078125 | J19: =(F20+F19)/2 -> 0.024902344 | K19: =(G20+G19)/2 -> 0.024902344 | L19: =((2*$B$11)/$B$8)-(2*$B$11*H19)/$B$8^2 -> 0.24375 | M19: =((2*$B$11)/$B$8)-(2*$B$11*H19)/$B$8^2 -> 0.24375 | O19: 3 | P19: =-2*PI()*($B$3-L19) -> 1.604622 | Q19: =-2*PI()*($B$3-M19) -> 1.604622 | V19: =E21-E20 -> 0.03125 | W19: =H20-E17 -> 0.109375 | X19: =H20-E18 -> 0.078125 | Y19: =H20-E19 -> 0.046875 | Z19: =H20-E20 -> 0.015625 | AA19: =H20-E21 -> -0.015625 | AB19: =H20-E22 -> -0.046875 | AC19: =H20-E23 -> -0.078125 | AD19: =H20-E24 -> -0.109375 | AE19: =H20-E25 -> -0.140625 | AF19: =H20-E26 -> -0.171875 | AG19: =H20-E27 -> -0.203125 | AH19: =H20-E28 -> -0.234375 | AI19: =H20-E29 -> -0.265625 | AJ19: =H20-E30 -> -0.296875 | AK19: =H20-E31 -> -0.328125 | AL19: =H20-E32 -> -0.359375 | AM19: =H20-E33 -> -0.390625 | AN19: =H20-E34 -> -0.421875 | AO19: =H20-E35 -> -0.453125 | AP19: =H20-E36 -> -0.484375 | AQ19: =H20-E37 -> -0.515625 | AR19: =H20-E38 -> -0.546875 | AS19: =H20-E39 -> -0.578125 | AT19: =H20-E40 -> -0.609375 | AU19: =H20-E41 -> -0.640625 | AV19: =H20-E42 -> -0.671875 | AW19: =H20-E43 -> -0.703125 | AX19: =H20-E44 -> -0.734375 | AY19: =H20-E45 -> -0.765625 | AZ19: =H20-E46 -> -0.796875 | BA19: =H20-E47 -> -0.828125 | BB19: =H20-E48 -> -0.859375 | BC19: =H20-$E$49 -> -0.890625 | BE19: 4 | BF19: =BZ85+AO85 -> -0.15881941 | BG19: =CA85+AP85 -> -0.41141439 | BH19: =CB85+AQ85 -> -0.72775792 | BI19: =CC85+AR85 -> -1.6479184 | BJ19: =CD85+AS85 -> 1.6479184 | BK19: =CE85+AT85 -> 0.72775792 | BL19: =CF85+AU85 -> 0.41141439 | BM19: =CG85+AV85 -> 0.28973434 | ... CK19: =DE85+BT85 -> 0.036371655 | CL19: 4 | CM19: 0.014534185 | CN19: 0.036580299 | CO19: 0.2288599 | CP19: -0.26581575 | CQ19: -0.07444268 | CR19: -0.056606046 | CS19: -0.04488331 | CT19: -0.038403511 | CU19: -0.034205532 | CV19: -0.031296403 | CW19: -0.029185313 | CX19: -0.027608978 | CY19: -0.026413617 | CZ19: -0.025504113 | DA19: -0.024819305 | DB19: -0.02431906 | DC19: -0.023977156 | DD19: -0.023777249 | DE19: -0.023710627 | DF19: -0.023775133 | DG19: -0.023974981 | DH19: -0.024321434 | DI19: -0.024834555 | DJ19: -0.025546581 | DK19: -0.026508126 | DL19: -0.027799826 | DM19: -0.029555551 | DN19: -0.032013795 | DO19: -0.035635295 | DP19: -0.041634958 | DQ19: -0.051019386 | DR19: -0.11705198
B20: 4 | E20: =$B$6*B19 -> 0.09375 | F20: =($B$11/$B$8^2)*(2*E20*$B$8-E20^2) -> 0.028710937 | G20: =($B$11/$B$8^2)*(2*E20*$B$8-E20^2) -> 0.028710937 | H20: =(E21+E20)/2 -> 0.109375 | I20: =(E21+E20)/2 -> 0.109375 | J20: =(F21+F20)/2 -> 0.031542969 | K20: =(G21+G20)/2 -> 0.031542969 | L20: =((2*$B$11)/$B$8)-(2*$B$11*H20)/$B$8^2 -> 0.18125 | M20: =((2*$B$11)/$B$8)-(2*$B$11*H20)/$B$8^2 -> 0.18125 | O20: 4 | P20: =-2*PI()*($B$3-L20) -> 1.2119229 | Q20: =-2*PI()*($B$3-M20) -> 1.2119229 | V20: =E22-E21 -> 0.03125 | W20: =H21-E17 -> 0.140625 | X20: =H21-E18 -> 0.109375 | Y20: =H21-E19 -> 0.078125 | Z20: =H21-E20 -> 0.046875 | AA20: =H21-E21 -> 0.015625 | AB20: =H21-E22 -> -0.015625 | AC20: =H21-E23 -> -0.046875 | AD20: =H21-E24 -> -0.078125 | AE20: =H21-E25 -> -0.109375 | AF20: =H21-E26 -> -0.140625 | AG20: =H21-E27 -> -0.171875 | AH20: =H21-E28 -> -0.203125 | AI20: =H21-E29 -> -0.234375 | AJ20: =H21-E30 -> -0.265625 | AK20: =H21-E31 -> -0.296875 | AL20: =H21-E32 -> -0.328125 | AM20: =H21-E33 -> -0.359375 | AN20: =H21-E34 -> -0.390625 | AO20: =H21-E35 -> -0.421875 | AP20: =H21-E36 -> -0.453125 | AQ20: =H21-E37 -> -0.484375 | AR20: =H21-E38 -> -0.515625 | AS20: =H21-E39 -> -0.546875 | AT20: =H21-E40 -> -0.578125 | AU20: =H21-E41 -> -0.609375 | AV20: =H21-E42 -> -0.640625 | AW20: =H21-E43 -> -0.671875 | AX20: =H21-E44 -> -0.703125 | AY20: =H21-E45 -> -0.734375 | AZ20: =H21-E46 -> -0.765625 | BA20: =H21-E47 -> -0.796875 | BB20: =H21-E48 -> -0.828125 | BC20: =H21-$E$49 -> -0.859375 | BE20: 5 | BF20: =BZ86+AO86 -> -0.1203995 | BG20: =CA86+AP86 -> -0.28973434 | BH20: =CB86+AQ86 -> -0.41141439 | BI20: =CC86+AR86 -> -0.72775792 | BJ20: =CD86+AS86 -> -1.6479184 | BK20: =CE86+AT86 -> 1.6479184 | BL20: =CF86+AU86 -> 0.72775792 | BM20: =CG86+AV86 -> 0.41141439 | ... CK20: =DE86+BT86 -> 0.03774481 | CL20: 5 | CM20: 0.0086146725 | CN20: 0.02327307 | CO20: 0.041761567 | CP20: 0.23317197 | CQ20: -0.26205149 | CR20: -0.071038658 | CS20: -0.053461552 | CT20: -0.041935548 | CU20: -0.035610311 | CV20: -0.031536955 | CW20: -0.028730305 | CX20: -0.026704808 | CY20: -0.025200896 | CZ20: -0.024067538 | DA20: -0.02321175 | DB20: -0.02257411 | DC20: -0.022116011 | DD20: -0.021812677 | DE20: -0.021649267 | DF20: -0.021618803 | DG20: -0.02172132 | DH20: -0.021964028 | DI20: -0.022362585 | DJ20: -0.02294389 | DK20: -0.023751433 | DL20: -0.024855507 | DM20: -0.02637367 | DN20: -0.028516145 | DO20: -0.031689818 | DP20: -0.03696879 | DQ20: -0.045242328 | DR20: -0.10363982
B21: 5 | E21: =$B$6*B20 -> 0.125 | F21: =($B$11/$B$8^2)*(2*E21*$B$8-E21^2) -> 0.034375 | G21: =($B$11/$B$8^2)*(2*E21*$B$8-E21^2) -> 0.034375 | H21: =(E22+E21)/2 -> 0.140625 | I21: =(E22+E21)/2 -> 0.140625 | J21: =(F22+F21)/2 -> 0.036230469 | K21: =(G22+G21)/2 -> 0.036230469 | L21: =((2*$B$11)/$B$8)-(2*$B$11*H21)/$B$8^2 -> 0.11875 | M21: =((2*$B$11)/$B$8)-(2*$B$11*H21)/$B$8^2 -> 0.11875 | O21: 5 | P21: =-2*PI()*($B$3-L21) -> 0.81922381 | Q21: =-2*PI()*($B$3-M21) -> 0.81922381 | V21: =E23-E22 -> 0.03125 | W21: =H22-E17 -> 0.171875 | X21: =H22-E18 -> 0.140625 | Y21: =H22-E19 -> 0.109375 | Z21: =H22-E20 -> 0.078125 | AA21: =H22-E21 -> 0.046875 | AB21: =H22-E22 -> 0.015625 | AC21: =H22-E23 -> -0.015625 | AD21: =H22-E24 -> -0.046875 | AE21: =H22-E25 -> -0.078125 | AF21: =H22-E26 -> -0.109375 | AG21: =H22-E27 -> -0.140625 | AH21: =H22-E28 -> -0.171875 | AI21: =H22-E29 -> -0.203125 | AJ21: =H22-E30 -> -0.234375 | AK21: =H22-E31 -> -0.265625 | AL21: =H22-E32 -> -0.296875 | AM21: =H22-E33 -> -0.328125 | AN21: =H22-E34 -> -0.359375 | AO21: =H22-E35 -> -0.390625 | AP21: =H22-E36 -> -0.421875 | AQ21: =H22-E37 -> -0.453125 | AR21: =H22-E38 -> -0.484375 | AS21: =H22-E39 -> -0.515625 | AT21: =H22-E40 -> -0.546875 | AU21: =H22-E41 -> -0.578125 | AV21: =H22-E42 -> -0.609375 | AW21: =H22-E43 -> -0.640625 | AX21: =H22-E44 -> -0.671875 | AY21: =H22-E45 -> -0.703125 | AZ21: =H22-E46 -> -0.734375 | BA21: =H22-E47 -> -0.765625 | BB21: =H22-E48 -> -0.796875 | BC21: =H22-$E$49 -> -0.828125 | BE21: 6 | BF21: =BZ87+AO87 -> -0.09698187 | BG21: =CA87+AP87 -> -0.22408833 | BH21: =CB87+AQ87 -> -0.28973434 | BI21: =CC87+AR87 -> -0.41141439 | BJ21: =CD87+AS87 -> -0.72775792 | BK21: =CE87+AT87 -> -1.6479184 | BL21: =CF87+AU87 -> 1.6479184 | BM21: =CG87+AV87 -> 0.72775792 | ... CK21: =DE87+BT87 -> 0.039225744 | CL21: 6 | CM21: 0.00590872 | CN21: 0.014575753 | CO21: 0.026806163 | CP21: 0.044697898 | CQ21: 0.2357313 | CR21: -0.25974107 | CS21: -0.068908461 | CT21: -0.051468824 | CU21: -0.040051691 | CV21: -0.033815138 | CW21: -0.029815672 | CX21: -0.027071782 | CY21: -0.025100541 | CZ21: -0.023644366 | DA21: -0.022553813 | DB21: -0.021737253 | DC21: -0.021136517 | DD21: -0.02071426 | DE21: -0.020447103 | DF21: -0.020321889 | DG21: -0.020333828 | DH21: -0.020485989 | DI21: -0.02079004 | DJ21: -0.021268521 | DK21: -0.021959546 | DL21: -0.022925978 | DM21: -0.024273995 | DN21: -0.026194411 | DO21: -0.029057431 | DP21: -0.033841653 | DQ21: -0.041356619 | DR21: -0.094582457
B22: 6 | E22: =$B$6*B21 -> 0.15625 | F22: =($B$11/$B$8^2)*(2*E22*$B$8-E22^2) -> 0.038085937 | G22: =($B$11/$B$8^2)*(2*E22*$B$8-E22^2) -> 0.038085937 | H22: =(E23+E22)/2 -> 0.171875 | I22: =(E23+E22)/2 -> 0.171875 | J22: =(F23+F22)/2 -> 0.038964844 | K22: =(G23+G22)/2 -> 0.038964844 | L22: =((2*$B$11)/$B$8)-(2*$B$11*H22)/$B$8^2 -> 0.05625 | M22: =((2*$B$11)/$B$8)-(2*$B$11*H22)/$B$8^2 -> 0.05625 | O22: 6 | P22: =-2*PI()*($B$3-L22) -> 0.42652473 | Q22: =-2*PI()*($B$3-M22) -> 0.42652473 | V22: =E24-E23 -> 0.03125 | W22: =H23-E17 -> 0.203125 | X22: =H23-E18 -> 0.171875 | Y22: =H23-E19 -> 0.140625 | Z22: =H23-E20 -> 0.109375 | AA22: =H23-E21 -> 0.078125 | AB22: =H23-E22 -> 0.046875 | AC22: =H23-E23 -> 0.015625 | AD22: =H23-E24 -> -0.015625 | AE22: =H23-E25 -> -0.046875 | AF22: =H23-E26 -> -0.078125 | AG22: =H23-E27 -> -0.109375 | AH22: =H23-E28 -> -0.140625 | AI22: =H23-E29 -> -0.171875 | AJ22: =H23-E30 -> -0.203125 | AK22: =H23-E31 -> -0.234375 | AL22: =H23-E32 -> -0.265625 | AM22: =H23-E33 -> -0.296875 | AN22: =H23-E34 -> -0.328125 | AO22: =H23-E35 -> -0.359375 | AP22: =H23-E36 -> -0.390625 | AQ22: =H23-E37 -> -0.421875 | AR22: =H23-E38 -> -0.453125 | AS22: =H23-E39 -> -0.484375 | AT22: =H23-E40 -> -0.515625 | AU22: =H23-E41 -> -0.546875 | AV22: =H23-E42 -> -0.578125 | AW22: =H23-E43 -> -0.609375 | AX22: =H23-E44 -> -0.640625 | AY22: =H23-E45 -> -0.671875 | AZ22: =H23-E46 -> -0.703125 | BA22: =H23-E47 -> -0.734375 | BB22: =H23-E48 -> -0.765625 | BC22: =H23-$E$49 -> -0.796875 | BE22: 7 | BF22: =BZ88+AO88 -> -0.081202534 | BG22: =CA88+AP88 -> -0.18283342 | BH22: =CB88+AQ88 -> -0.22408833 | BI22: =CC88+AR88 -> -0.28973434 | BJ22: =CD88+AS88 -> -0.41141439 | BK22: =CE88+AT88 -> -0.72775792 | BL22: =CF88+AU88 -> -1.6479184 | BM22: =CG88+AV88 -> 1.6479184 | ... CK22: =DE88+BT88 -> 0.040827667 | CL22: 7 | CM22: 0.0043256022 | CN22: 0.010241912 | CO22: 0.017143726 | CP22: 0.028937154 | CQ22: 0.04655212 | CR22: 0.23740196 | CS22: -0.25820402 | CT22: -0.067474 | CU22: -0.050116301 | CV22: -0.038766619 | CW22: -0.032587013 | CX22: -0.028636713 | CY22: -0.025936195 | CZ22: -0.024004061 | DA22: -0.02258399 | DB22: -0.021527657 | DC22: -0.020744517 | DD22: -0.020177543 | DE22: -0.019790705 | DF22: -0.019562251 | DG22: -0.019481175 | DH22: -0.019545697 | DI22: -0.019763302 | DJ22: -0.020152458 | DK22: -0.020746718 | DL22: -0.021603086 | DM22: -0.022819164 | DN22: -0.024571501 | DO22: -0.027203681 | DP22: -0.031625474 | DQ22: -0.038588827 | DR22: -0.088095328
B23: 7 | E23: =$B$6*B22 -> 0.1875 | F23: =($B$11/$B$8^2)*(2*E23*$B$8-E23^2) -> 0.03984375 | G23: =($B$11/$B$8^2)*(2*E23*$B$8-E23^2) -> 0.03984375 | H23: =(E24+E23)/2 -> 0.203125 | I23: =(E24+E23)/2 -> 0.203125 | J23: =(F24+F23)/2 -> 0.039910889 | K23: =(G24+G23)/2 -> 0.039910889 | L23: =((2*$B$11)/$B$8)-(2*$B$11*H23)/$B$8^2 -> -0.00625 | M23: =((2*$B$11)/$B$8)-(2*$B$11*H23)/$B$8^2 -> -0.00625 | O23: 7 | P23: =-2*PI()*($B$3-L23) -> 0.033825646 | Q23: =-2*PI()*($B$3-M23) -> 0.033825646 | V23: =E25-E24 -> 0.03125 | W23: =H24-E17 -> 0.234375 | X23: =H24-E18 -> 0.203125 | Y23: =H24-E19 -> 0.171875 | Z23: =H24-E20 -> 0.140625 | AA23: =H24-E21 -> 0.109375 | AB23: =H24-E22 -> 0.078125 | AC23: =H24-E23 -> 0.046875 | AD23: =H24-E24 -> 0.015625 | AE23: =H24-E25 -> -0.015625 | AF23: =H24-E26 -> -0.046875 | AG23: =H24-E27 -> -0.078125 | AH23: =H24-E28 -> -0.109375 | AI23: =H24-E29 -> -0.140625 | AJ23: =H24-E30 -> -0.171875 | AK23: =H24-E31 -> -0.203125 | AL23: =H24-E32 -> -0.234375 | AM23: =H24-E33 -> -0.265625 | AN23: =H24-E34 -> -0.296875 | AO23: =H24-E35 -> -0.328125 | AP23: =H24-E36 -> -0.359375 | AQ23: =H24-E37 -> -0.390625 | AR23: =H24-E38 -> -0.421875 | AS23: =H24-E39 -> -0.453125 | AT23: =H24-E40 -> -0.484375 | AU23: =H24-E41 -> -0.515625 | AV23: =H24-E42 -> -0.546875 | AW23: =H24-E43 -> -0.578125 | AX23: =H24-E44 -> -0.609375 | AY23: =H24-E45 -> -0.640625 | AZ23: =H24-E46 -> -0.671875 | BA23: =H24-E47 -> -0.703125 | BB23: =H24-E48 -> -0.734375 | BC23: =H24-$E$49 -> -0.765625 | BE23: 8 | BF23: =BZ89+AO89 -> -0.069844516 | BG23: =CA89+AP89 -> -0.15445886 | BH23: =CB89+AQ89 -> -0.18283342 | BI23: =CC89+AR89 -> -0.22408833 | BJ23: =CD89+AS89 -> -0.28973434 | BK23: =CE89+AT89 -> -0.41141439 | BL23: =CF89+AU89 -> -0.72775792 | BM23: =CG89+AV89 -> -1.6479184 | ... CK23: =DE89+BT89 -> 0.042566043 | CL23: 8 | CM23: 0.0033184835 | CN23: 0.007632801 | CO23: 0.012200286 | CP23: 0.018766087 | CQ23: 0.0303461 | CR23: 0.047818872 | CS23: 0.23856465 | CT23: -0.2571218 | CU23: -0.066456602 | CV23: -0.049152826 | CW23: -0.037849259 | CX23: -0.031710093 | CY23: -0.027796134 | CZ23: -0.025129098 | DA23: -0.023228637 | DB23: -0.021839397 | DC23: -0.020814024 | DD23: -0.020063028 | DE23: -0.019530633 | DF23: -0.019182386 | DG23: -0.018998641 | DH23: -0.018971354 | DI23: -0.019103088 | DJ23: -0.019408004 | DK23: -0.019915342 | DL23: -0.020677052 | DM23: -0.021783809 | DN23: -0.023401081 | DO23: -0.025852188 | DP23: -0.029995049 | DQ23: -0.036538103 | DR23: -0.083252663
B24: 8 | E24: =$B$6*B23 -> 0.21875 | F24: =($B$11/(1-$B$8)^2)*(1-2*$B$8+2*$B$8*E24-E24^2) -> 0.039978027 | G24: =($B$11/(1-$B$8)^2)*(1-2*$B$8+2*$B$8*E24-E24^2) -> 0.039978027 | H24: =(E25+E24)/2 -> 0.234375 | I24: =(E25+E24)/2 -> 0.234375 | J24: =(F25+F24)/2 -> 0.039910889 | K24: =(G25+G24)/2 -> 0.039910889 | L24: =(2*$B$8*$B$11-2*$B$11*H24)/(1-$B$8)^2 -> -0.004296875 | M24: =(2*$B$8*$B$11-2*$B$11*H24)/(1-$B$8)^2 -> -0.004296875 | O24: 8 | P24: =-2*PI()*($B$3-L24) -> 0.046097492 | Q24: =-2*PI()*($B$3-M24) -> 0.046097492 | V24: =E26-E25 -> 0.03125 | W24: =H25-E17 -> 0.265625 | X24: =H25-E18 -> 0.234375 | Y24: =H25-E19 -> 0.203125 | Z24: =H25-E20 -> 0.171875 | AA24: =H25-E21 -> 0.140625 | AB24: =H25-E22 -> 0.109375 | AC24: =H25-E23 -> 0.078125 | AD24: =H25-E24 -> 0.046875 | AE24: =H25-E25 -> 0.015625 | AF24: =H25-E26 -> -0.015625 | AG24: =H25-E27 -> -0.046875 | AH24: =H25-E28 -> -0.078125 | AI24: =H25-E29 -> -0.109375 | AJ24: =H25-E30 -> -0.140625 | AK24: =H25-E31 -> -0.171875 | AL24: =H25-E32 -> -0.203125 | AM24: =H25-E33 -> -0.234375 | AN24: =H25-E34 -> -0.265625 | AO24: =H25-E35 -> -0.296875 | AP24: =H25-E36 -> -0.328125 | AQ24: =H25-E37 -> -0.359375 | AR24: =H25-E38 -> -0.390625 | AS24: =H25-E39 -> -0.421875 | AT24: =H25-E40 -> -0.453125 | AU24: =H25-E41 -> -0.484375 | AV24: =H25-E42 -> -0.515625 | AW24: =H25-E43 -> -0.546875 | AX24: =H25-E44 -> -0.578125 | AY24: =H25-E45 -> -0.609375 | AZ24: =H25-E46 -> -0.640625 | BA24: =H25-E47 -> -0.671875 | BB24: =H25-E48 -> -0.703125 | BC24: =H25-$E$49 -> -0.734375 | BE24: 9 | BF24: =BZ90+AO90 -> -0.061276428 | BG24: =CA90+AP90 -> -0.13373123 | BH24: =CB90+AQ90 -> -0.15445886 | BI24: =CC90+AR90 -> -0.18283342 | BJ24: =CD90+AS90 -> -0.22408833 | BK24: =CE90+AT90 -> -0.28973434 | BL24: =CF90+AU90 -> -0.41141439 | BM24: =CG90+AV90 -> -0.72775792 | ... CK24: =DE90+BT90 -> 0.044459088 | CL24: 9 | CM24: 0.0026322925 | CN24: 0.0059308195 | CO24: 0.0091777651 | CP24: 0.013477753 | CQ24: 0.01987314 | CR24: 0.031339064 | CS24: 0.048727852 | CT24: 0.23940822 | CU24: -0.25633136 | CV24: -0.065710846 | CW24: -0.048445765 | CX24: -0.03717664 | CY24: -0.031068956 | CZ24: -0.027184562 | DA24: -0.02454608 | DB24: -0.022674022 | DC24: -0.021313921 | DD24: -0.020319418 | DE24: -0.019602223 | DF24: -0.019108093 | DG24: -0.018804639 | DH24: -0.018675122 | DI24: -0.018715768 | DJ24: -0.018935691 | DK24: -0.019359594 | DL24: -0.020034669 | DM24: -0.021045613 | DN24: -0.022548877 | DO24: -0.024851793 | DP24: -0.028772052 | DQ24: -0.034984213 | DR24: -0.079544858
B25: 9 | E25: =$B$6*B24 -> 0.25 | F25: =($B$11/(1-$B$8)^2)*(1-2*$B$8+2*$B$8*E25-E25^2) -> 0.03984375 | G25: =($B$11/(1-$B$8)^2)*(1-2*$B$8+2*$B$8*E25-E25^2) -> 0.03984375 | H25: =(E26+E25)/2 -> 0.265625 | I25: =(E26+E25)/2 -> 0.265625 | J25: =(F26+F25)/2 -> 0.039715576 | K25: =(G26+G25)/2 -> 0.039715576 | L25: =(2*$B$8*$B$11-2*$B$11*H25)/(1-$B$8)^2 -> -0.008203125 | M25: =(2*$B$8*$B$11-2*$B$11*H25)/(1-$B$8)^2 -> -0.008203125 | O25: 9 | P25: =-2*PI()*($B$3-L25) -> 0.0215538 | Q25: =-2*PI()*($B$3-M25) -> 0.0215538 | V25: =E27-E26 -> 0.03125 | W25: =H26-E17 -> 0.296875 | X25: =H26-E18 -> 0.265625 | Y25: =H26-E19 -> 0.234375 | Z25: =H26-E20 -> 0.203125 | AA25: =H26-E21 -> 0.171875 | AB25: =H26-E22 -> 0.140625 | AC25: =H26-E23 -> 0.109375 | AD25: =H26-E24 -> 0.078125 | AE25: =H26-E25 -> 0.046875 | AF25: =H26-E26 -> 0.015625 | AG25: =H26-E27 -> -0.015625 | AH25: =H26-E28 -> -0.046875 | AI25: =H26-E29 -> -0.078125 | AJ25: =H26-E30 -> -0.109375 | AK25: =H26-E31 -> -0.140625 | AL25: =H26-E32 -> -0.171875 | AM25: =H26-E33 -> -0.203125 | AN25: =H26-E34 -> -0.234375 | AO25: =H26-E35 -> -0.265625 | AP25: =H26-E36 -> -0.296875 | AQ25: =H26-E37 -> -0.328125 | AR25: =H26-E38 -> -0.359375 | AS25: =H26-E39 -> -0.390625 | AT25: =H26-E40 -> -0.421875 | AU25: =H26-E41 -> -0.453125 | AV25: =H26-E42 -> -0.484375 | AW25: =H26-E43 -> -0.515625 | AX25: =H26-E44 -> -0.546875 | AY25: =H26-E45 -> -0.578125 | AZ25: =H26-E46 -> -0.609375 | BA25: =H26-E47 -> -0.640625 | BB25: =H26-E48 -> -0.671875 | BC25: =H26-$E$49 -> -0.703125 | BE25: 10 | BF25: =BZ91+AO91 -> -0.054582102 | BG25: =CA91+AP91 -> -0.11791996 | BH25: =CB91+AQ91 -> -0.13373123 | BI25: =CC91+AR91 -> -0.15445886 | BJ25: =CD91+AS91 -> -0.18283342 | BK25: =CE91+AT91 -> -0.22408833 | BL25: =CF91+AU91 -> -0.28973434 | BM25: =CG91+AV91 -> -0.41141439 | ... CK25: =DE91+BT91 -> 0.046528412 | CL25: 10 | CM25: 0.0021408818 | CN25: 0.0047493948 | CO25: 0.0071808267 | CP25: 0.010209181 | CQ25: 0.014369457 | CR25: 0.020670836 | CS25: 0.032067138 | CT25: 0.049401308 | CU25: 0.2400369 | CV25: -0.25574073 | CW25: -0.065153572 | CX25: -0.047918606 | CY25: -0.036677444 | CZ25: -0.030596473 | DA25: -0.026738343 | DB25: -0.024126456 | DC25: -0.022282153 | DD25: -0.020951913 | DE25: -0.019990537 | DF25: -0.019311231 | DG25: -0.01886178 | DH25: -0.018612652 | DI25: -0.018551311 | DJ25: -0.01868042 | DK25: -0.019019434 | DL25: -0.019610629 | DM25: -0.020533168 | DN25: -0.021935812 | DO25: -0.024112894 | DP25: -0.027850253 | DQ25: -0.03379549 | DR25: -0.076666202
B26: 10 | E26: =$B$6*B25 -> 0.28125 | F26: =($B$11/(1-$B$8)^2)*(1-2*$B$8+2*$B$8*E26-E26^2) -> 0.039587402 | G26: =($B$11/(1-$B$8)^2)*(1-2*$B$8+2*$B$8*E26-E26^2) -> 0.039587402 | H26: =(E27+E26)/2 -> 0.296875 | I26: =(E27+E26)/2 -> 0.296875 | J26: =(F27+F26)/2 -> 0.039398193 | K26: =(G27+G26)/2 -> 0.039398193 | L26: =(2*$B$8*$B$11-2*$B$11*H26)/(1-$B$8)^2 -> -0.012109375 | M26: =(2*$B$8*$B$11-2*$B$11*H26)/(1-$B$8)^2 -> -0.012109375 | O26: 10 | P26: =-2*PI()*($B$3-L26) -> -0.0029898928 | Q26: =-2*PI()*($B$3-M26) -> -0.0029898928 | V26: =E28-E27 -> 0.03125 | W26: =H27-E17 -> 0.328125 | X26: =H27-E18 -> 0.296875 | Y26: =H27-E19 -> 0.265625 | Z26: =H27-E20 -> 0.234375 | AA26: =H27-E21 -> 0.203125 | AB26: =H27-E22 -> 0.171875 | AC26: =H27-E23 -> 0.140625 | AD26: =H27-E24 -> 0.109375 | AE26: =H27-E25 -> 0.078125 | AF26: =H27-E26 -> 0.046875 | AG26: =H27-E27 -> 0.015625 | AH26: =H27-E28 -> -0.015625 | AI26: =H27-E29 -> -0.046875 | AJ26: =H27-E30 -> -0.078125 | AK26: =H27-E31 -> -0.109375 | AL26: =H27-E32 -> -0.140625 | AM26: =H27-E33 -> -0.171875 | AN26: =H27-E34 -> -0.203125 | AO26: =H27-E35 -> -0.234375 | AP26: =H27-E36 -> -0.265625 | AQ26: =H27-E37 -> -0.296875 | AR26: =H27-E38 -> -0.328125 | AS26: =H27-E39 -> -0.359375 | AT26: =H27-E40 -> -0.390625 | AU26: =H27-E41 -> -0.421875 | AV26: =H27-E42 -> -0.453125 | AW26: =H27-E43 -> -0.484375 | AX26: =H27-E44 -> -0.515625 | AY26: =H27-E45 -> -0.546875 | AZ26: =H27-E46 -> -0.578125 | BA26: =H27-E47 -> -0.609375 | BB26: =H27-E48 -> -0.640625 | BC26: =H27-$E$49 -> -0.671875 | BE26: 11 | BF26: =BZ92+AO92 -> -0.049207144 | BG26: =CA92+AP92 -> -0.10545842 | BH26: =CB92+AQ92 -> -0.11791996 | BI26: =CC92+AR92 -> -0.13373123 | BJ26: =CD92+AS92 -> -0.15445886 | BK26: =CE92+AT92 -> -0.18283342 | BL26: =CF92+AU92 -> -0.22408833 | BM26: =CG92+AV92 -> -0.28973434 | ... CK26: =DE92+BT92 -> 0.048799852 | CL26: 11 | CM26: 0.0017751451 | CN26: 0.0038908124 | CO26: 0.0057805232 | CP26: 0.0080296655 | CQ26: 0.0109411 | CR26: 0.015022282 | CS26: 0.021264714 | CT26: 0.032614417 | CU26: 0.049910036 | CV26: 0.24051253 | CW26: -0.25529449 | CX26: -0.064734206 | CY26: -0.047524567 | CZ26: -0.036307974 | DA26: -0.030251533 | DB26: -0.02641862 | DC26: -0.023833417 | DD26: -0.022018175 | DE26: -0.020720502 | DF26: -0.019796665 | DG26: -0.019161865 | DH26: -0.018766705 | DI26: -0.018585796 | DJ26: -0.018612945 | DK26: -0.018860986 | DL26: -0.019366632 | DM26: -0.020203503 | DN26: -0.021513439 | DO26: -0.02357989 | DP26: -0.027163102 | DQ26: -0.032888903 | DR26: -0.074422715
B27: 11 | E27: =$B$6*B26 -> 0.3125 | F27: =($B$11/(1-$B$8)^2)*(1-2*$B$8+2*$B$8*E27-E27^2) -> 0.039208984 | G27: =($B$11/(1-$B$8)^2)*(1-2*$B$8+2*$B$8*E27-E27^2) -> 0.039208984 | H27: =(E28+E27)/2 -> 0.328125 | I27: =(E28+E27)/2 -> 0.328125 | J27: =(F28+F27)/2 -> 0.03895874 | K27: =(G28+G27)/2 -> 0.03895874 | L27: =(2*$B$8*$B$11-2*$B$11*H27)/(1-$B$8)^2 -> -0.016015625 | M27: =(2*$B$8*$B$11-2*$B$11*H27)/(1-$B$8)^2 -> -0.016015625 | O27: 11 | P27: =-2*PI()*($B$3-L27) -> -0.027533585 | Q27: =-2*PI()*($B$3-M27) -> -0.027533585 | V27: =E29-E28 -> 0.03125 | W27: =H28-E17 -> 0.359375 | X27: =H28-E18 -> 0.328125 | Y27: =H28-E19 -> 0.296875 | Z27: =H28-E20 -> 0.265625 | AA27: =H28-E21 -> 0.234375 | AB27: =H28-E22 -> 0.203125 | AC27: =H28-E23 -> 0.171875 | AD27: =H28-E24 -> 0.140625 | AE27: =H28-E25 -> 0.109375 | AF27: =H28-E26 -> 0.078125 | AG27: =H28-E27 -> 0.046875 | AH27: =H28-E28 -> 0.015625 | AI27: =H28-E29 -> -0.015625 | AJ27: =H28-E30 -> -0.046875 | AK27: =H28-E31 -> -0.078125 | AL27: =H28-E32 -> -0.109375 | AM27: =H28-E33 -> -0.140625 | AN27: =H28-E34 -> -0.171875 | AO27: =H28-E35 -> -0.203125 | AP27: =H28-E36 -> -0.234375 | AQ27: =H28-E37 -> -0.265625 | AR27: =H28-E38 -> -0.296875 | AS27: =H28-E39 -> -0.328125 | AT27: =H28-E40 -> -0.359375 | AU27: =H28-E41 -> -0.390625 | AV27: =H28-E42 -> -0.421875 | AW27: =H28-E43 -> -0.453125 | AX27: =H28-E44 -> -0.484375 | AY27: =H28-E45 -> -0.515625 | AZ27: =H28-E46 -> -0.546875 | BA27: =H28-E47 -> -0.578125 | BB27: =H28-E48 -> -0.609375 | BC27: =H28-$E$49 -> -0.640625 | BE27: 12 | BF27: =BZ93+AO93 -> -0.044796329 | BG27: =CA93+AP93 -> -0.095382593 | BH27: =CB93+AQ93 -> -0.10545842 | BI27: =CC93+AR93 -> -0.11791996 | BJ27: =CD93+AS93 -> -0.13373123 | BK27: =CE93+AT93 -> -0.15445886 | BL27: =CF93+AU93 -> -0.18283342 | BM27: =CG93+AV93 -> -0.22408833 | ... CK27: =DE93+BT93 -> 0.051304552 | CL27: 12 | CM27: 0.0014944777 | CN27: 0.0032441832 | CO27: 0.0047543627 | CP27: 0.0064895755 | CQ27: 0.0086392474 | CR27: 0.011483011 | CS27: 0.015513422 | CT27: 0.021715398 | CU27: 0.033031324 | CV27: 0.050297629 | CW27: 0.2408738 | CX27: -0.25495761 | CY27: -0.064420634 | CZ27: -0.047233911 | DA27: -0.036040512 | DB27: -0.030008221 | DC27: -0.026201158 | DD27: -0.023644389 | DE27: -0.021861266 | DF27: -0.020600842 | DG27: -0.019721352 | DH27: -0.019140784 | DI27: -0.018813834 | DJ27: -0.01872138 | DK27: -0.018867266 | DL27: -0.019281334 | DM27: -0.020031141 | DN27: -0.021251887 | DO27: -0.023217581 | DP27: -0.026667694 | DQ27: -0.032210247 | DR27: -0.072686357
B28: 12 | E28: =$B$6*B27 -> 0.34375 | F28: =($B$11/(1-$B$8)^2)*(1-2*$B$8+2*$B$8*E28-E28^2) -> 0.038708496 | G28: =($B$11/(1-$B$8)^2)*(1-2*$B$8+2*$B$8*E28-E28^2) -> 0.038708496 | H28: =(E29+E28)/2 -> 0.359375 | I28: =(E29+E28)/2 -> 0.359375 | J28: =(F29+F28)/2 -> 0.038397217 | K28: =(G29+G28)/2 -> 0.038397217 | L28: =(2*$B$8*$B$11-2*$B$11*H28)/(1-$B$8)^2 -> -0.019921875 | M28: =(2*$B$8*$B$11-2*$B$11*H28)/(1-$B$8)^2 -> -0.019921875 | O28: 12 | P28: =-2*PI()*($B$3-L28) -> -0.052077278 | Q28: =-2*PI()*($B$3-M28) -> -0.052077278 | V28: =E30-E29 -> 0.03125 | W28: =H29-E17 -> 0.390625 | X28: =H29-E18 -> 0.359375 | Y28: =H29-E19 -> 0.328125 | Z28: =H29-E20 -> 0.296875 | AA28: =H29-E21 -> 0.265625 | AB28: =H29-E22 -> 0.234375 | AC28: =H29-E23 -> 0.203125 | AD28: =H29-E24 -> 0.171875 | AE28: =H29-E25 -> 0.140625 | AF28: =H29-E26 -> 0.109375 | AG28: =H29-E27 -> 0.078125 | AH28: =H29-E28 -> 0.046875 | AI28: =H29-E29 -> 0.015625 | AJ28: =H29-E30 -> -0.015625 | AK28: =H29-E31 -> -0.046875 | AL28: =H29-E32 -> -0.078125 | AM28: =H29-E33 -> -0.109375 | AN28: =H29-E34 -> -0.140625 | AO28: =H29-E35 -> -0.171875 | AP28: =H29-E36 -> -0.203125 | AQ28: =H29-E37 -> -0.234375 | AR28: =H29-E38 -> -0.265625 | AS28: =H29-E39 -> -0.296875 | AT28: =H29-E40 -> -0.328125 | AU28: =H29-E41 -> -0.359375 | AV28: =H29-E42 -> -0.390625 | AW28: =H29-E43 -> -0.421875 | AX28: =H29-E44 -> -0.453125 | AY28: =H29-E45 -> -0.484375 | AZ28: =H29-E46 -> -0.515625 | BA28: =H29-E47 -> -0.546875 | BB28: =H29-E48 -> -0.578125 | BC28: =H29-$E$49 -> -0.609375 | BE28: 13 | BF28: =BZ94+AO94 -> -0.041111497 | BG28: =CA94+AP94 -> -0.087066441 | BH28: =CB94+AQ94 -> -0.095382593 | BI28: =CC94+AR94 -> -0.10545842 | BJ28: =CD94+AS94 -> -0.11791996 | BK28: =CE94+AT94 -> -0.13373123 | BL28: =CF94+AU94 -> -0.15445886 | BM28: =CG94+AV94 -> -0.18283342 | ... CK28: =DE94+BT94 -> 0.054080408 | CL28: 13 | CM28: 0.0012736438 | CN28: 0.002743069 | CO28: 0.0039761173 | CP28: 0.005353616 | CQ28: 0.007003055 | CR28: 0.0090940217 | CS28: 0.011893432 | CT28: 0.01588821 | CU28: 0.022060153 | CV28: 0.033349737 | CW28: 0.050592113 | CX28: 0.24114583 | CY28: -0.25470729 | CZ28: -0.06419194 | DA28: -0.047027368 | DB28: -0.035857288 | DC28: -0.029850202 | DD28: -0.02607109 | DE28: -0.023546101 | DF28: -0.021800014 | DG28: -0.020583831 | DH28: -0.019758548 | DI28: -0.019246212 | DJ28: -0.019007726 | DK28: -0.019033905 | DL28: -0.01934541 | DM28: -0.020002546 | DN28: -0.021133613 | DO28: -0.02300405 | DP28: -0.026336282 | DQ28: -0.031723625 | DR28: -0.071370587
B29: 13 | E29: =$B$6*B28 -> 0.375 | F29: =($B$11/(1-$B$8)^2)*(1-2*$B$8+2*$B$8*E29-E29^2) -> 0.038085937 | G29: =($B$11/(1-$B$8)^2)*(1-2*$B$8+2*$B$8*E29-E29^2) -> 0.038085937 | H29: =(E30+E29)/2 -> 0.390625 | I29: =(E30+E29)/2 -> 0.390625 | J29: =(F30+F29)/2 -> 0.037713623 | K29: =(G30+G29)/2 -> 0.037713623 | L29: =(2*$B$8*$B$11-2*$B$11*H29)/(1-$B$8)^2 -> -0.023828125 | M29: =(2*$B$8*$B$11-2*$B$11*H29)/(1-$B$8)^2 -> -0.023828125 | O29: 13 | P29: =-2*PI()*($B$3-L29) -> -0.076620971 | Q29: =-2*PI()*($B$3-M29) -> -0.076620971 | V29: =E31-E30 -> 0.03125 | W29: =H30-E17 -> 0.421875 | X29: =H30-E18 -> 0.390625 | Y29: =H30-E19 -> 0.359375 | Z29: =H30-E20 -> 0.328125 | AA29: =H30-E21 -> 0.296875 | AB29: =H30-E22 -> 0.265625 | AC29: =H30-E23 -> 0.234375 | AD29: =H30-E24 -> 0.203125 | AE29: =H30-E25 -> 0.171875 | AF29: =H30-E26 -> 0.140625 | AG29: =H30-E27 -> 0.109375 | AH29: =H30-E28 -> 0.078125 | AI29: =H30-E29 -> 0.046875 | AJ29: =H30-E30 -> 0.015625 | AK29: =H30-E31 -> -0.015625 | AL29: =H30-E32 -> -0.046875 | AM29: =H30-E33 -> -0.078125 | AN29: =H30-E34 -> -0.109375 | AO29: =H30-E35 -> -0.140625 | AP29: =H30-E36 -> -0.171875 | AQ29: =H30-E37 -> -0.203125 | AR29: =H30-E38 -> -0.234375 | AS29: =H30-E39 -> -0.265625 | AT29: =H30-E40 -> -0.296875 | AU29: =H30-E41 -> -0.328125 | AV29: =H30-E42 -> -0.359375 | AW29: =H30-E43 -> -0.390625 | AX29: =H30-E44 -> -0.421875 | AY29: =H30-E45 -> -0.453125 | AZ29: =H30-E46 -> -0.484375 | BA29: =H30-E47 -> -0.515625 | BB29: =H30-E48 -> -0.546875 | BC29: =H30-$E$49 -> -0.578125 | BE29: 14 | BF29: =BZ95+AO95 -> -0.037986986 | BG29: =CA95+AP95 -> -0.080085553 | BH29: =CB95+AQ95 -> -0.087066441 | BI29: =CC95+AR95 -> -0.095382593 | BJ29: =CD95+AS95 -> -0.10545842 | BK29: =CE95+AT95 -> -0.11791996 | BL29: =CF95+AU95 -> -0.13373123 | BM29: =CG95+AV95 -> -0.15445886 | ... CK29: =DE95+BT95 -> 0.057173996 | CL29: 14 | CM29: 0.0010962323 | CN29: 0.0023455073 | CO29: 0.0033694066 | CP29: 0.0044872604 | CQ29: 0.0057899594 | CR29: 0.0073878748 | CS29: 0.009439626 | CT29: 0.012207261 | CU29: 0.016174998 | CV29: 0.022322972 | CW29: 0.033590535 | CX29: 0.050812008 | CY29: 0.24134527 | CZ29: -0.25452846 | DA29: -0.064034444 | DB29: -0.046892548 | DC29: -0.035747182 | DD29: -0.029767691 | DE29: -0.026020124 | DF29: -0.023532044 | DG29: -0.021830166 | DH29: -0.020668237 | DI29: -0.019911287 | DJ29: -0.019487531 | DK29: -0.01936774 | DL29: -0.019559412 | DM29: -0.0201134 | DN29: -0.02115015 | DO29: -0.022926797 | DP29: -0.026151594 | DQ29: -0.031405547 | DR29: -0.070416552
B30: 14 | E30: =$B$6*B29 -> 0.40625 | F30: =($B$11/(1-$B$8)^2)*(1-2*$B$8+2*$B$8*E30-E30^2) -> 0.037341309 | G30: =($B$11/(1-$B$8)^2)*(1-2*$B$8+2*$B$8*E30-E30^2) -> 0.037341309 | H30: =(E31+E30)/2 -> 0.421875 | I30: =(E31+E30)/2 -> 0.421875 | J30: =(F31+F30)/2 -> 0.036907959 | K30: =(G31+G30)/2 -> 0.036907959 | L30: =(2*$B$8*$B$11-2*$B$11*H30)/(1-$B$8)^2 -> -0.027734375 | M30: =(2*$B$8*$B$11-2*$B$11*H30)/(1-$B$8)^2 -> -0.027734375 | O30: 14 | P30: =-2*PI()*($B$3-L30) -> -0.10116466 | Q30: =-2*PI()*($B$3-M30) -> -0.10116466 | V30: =E32-E31 -> 0.03125 | W30: =H31-E17 -> 0.453125 | X30: =H31-E18 -> 0.421875 | Y30: =H31-E19 -> 0.390625 | Z30: =H31-E20 -> 0.359375 | AA30: =H31-E21 -> 0.328125 | AB30: =H31-E22 -> 0.296875 | AC30: =H31-E23 -> 0.265625 | AD30: =H31-E24 -> 0.234375 | AE30: =H31-E25 -> 0.203125 | AF30: =H31-E26 -> 0.171875 | AG30: =H31-E27 -> 0.140625 | AH30: =H31-E28 -> 0.109375 | AI30: =H31-E29 -> 0.078125 | AJ30: =H31-E30 -> 0.046875 | AK30: =H31-E31 -> 0.015625 | AL30: =H31-E32 -> -0.015625 | AM30: =H31-E33 -> -0.046875 | AN30: =H31-E34 -> -0.078125 | AO30: =H31-E35 -> -0.109375 | AP30: =H31-E36 -> -0.140625 | AQ30: =H31-E37 -> -0.171875 | AR30: =H31-E38 -> -0.203125 | AS30: =H31-E39 -> -0.234375 | AT30: =H31-E40 -> -0.265625 | AU30: =H31-E41 -> -0.296875 | AV30: =H31-E42 -> -0.328125 | AW30: =H31-E43 -> -0.359375 | AX30: =H31-E44 -> -0.390625 | AY30: =H31-E45 -> -0.421875 | AZ30: =H31-E46 -> -0.453125 | BA30: =H31-E47 -> -0.484375 | BB30: =H31-E48 -> -0.515625 | BC30: =H31-$E$49 -> -0.546875 | BE30: 15 | BF30: =BZ96+AO96 -> -0.035303986 | BG30: =CA96+AP96 -> -0.074141964 | BH30: =CB96+AQ96 -> -0.080085553 | BI30: =CC96+AR96 -> -0.087066441 | BJ30: =CD96+AS96 -> -0.095382593 | BK30: =CE96+AT96 -> -0.10545842 | BL30: =CF96+AU96 -> -0.11791996 | BM30: =CG96+AV96 -> -0.13373123 | ... CK30: =DE96+BT96 -> 0.060643217 | CL30: 15 | CM30: 0.00095116355 | CN30: 0.002023836 | CO30: 0.0028855741 | CP30: 0.0038085402 | CQ30: 0.0048605392 | CR30: 0.006117564 | CS30: 0.0076804442 | CT30: 0.0097035543 | CU30: 0.012446576 | CV30: 0.016392264 | CW30: 0.022519756 | CX30: 0.033767656 | CY30: 0.050969674 | CZ30: 0.24148313 | DA30: -0.2544113 | DB30: -0.063939465 | DC30: -0.046821923 | DD30: -0.035703909 | DE30: -0.029755829 | DF30: -0.026045137 | DG30: -0.023601324 | DH30: -0.021953842 | DI30: -0.02086046 | DJ30: -0.020192355 | DK30: -0.019887572 | DL30: -0.019933486 | DM30: -0.020367618 | DN30: -0.021300578 | DO30: -0.022980733 | DP30: -0.026104234 | DQ30: -0.031241565 | DR30: -0.069784981
B31: 15 | E31: =$B$6*B30 -> 0.4375 | F31: =($B$11/(1-$B$8)^2)*(1-2*$B$8+2*$B$8*E31-E31^2) -> 0.036474609 | G31: =($B$11/(1-$B$8)^2)*(1-2*$B$8+2*$B$8*E31-E31^2) -> 0.036474609 | H31: =(E32+E31)/2 -> 0.453125 | I31: =(E32+E31)/2 -> 0.453125 | J31: =(F32+F31)/2 -> 0.035980225 | K31: =(G32+G31)/2 -> 0.035980225 | L31: =(2*$B$8*$B$11-2*$B$11*H31)/(1-$B$8)^2 -> -0.031640625 | M31: =(2*$B$8*$B$11-2*$B$11*H31)/(1-$B$8)^2 -> -0.031640625 | O31: 15 | P31: =-2*PI()*($B$3-L31) -> -0.12570836 | Q31: =-2*PI()*($B$3-M31) -> -0.12570836 | V31: =E33-E32 -> 0.03125 | W31: =H32-E17 -> 0.484375 | X31: =H32-E18 -> 0.453125 | Y31: =H32-E19 -> 0.421875 | Z31: =H32-E20 -> 0.390625 | AA31: =H32-E21 -> 0.359375 | AB31: =H32-E22 -> 0.328125 | AC31: =H32-E23 -> 0.296875 | AD31: =H32-E24 -> 0.265625 | AE31: =H32-E25 -> 0.234375 | AF31: =H32-E26 -> 0.203125 | AG31: =H32-E27 -> 0.171875 | AH31: =H32-E28 -> 0.140625 | AI31: =H32-E29 -> 0.109375 | AJ31: =H32-E30 -> 0.078125 | AK31: =H32-E31 -> 0.046875 | AL31: =H32-E32 -> 0.015625 | AM31: =H32-E33 -> -0.015625 | AN31: =H32-E34 -> -0.046875 | AO31: =H32-E35 -> -0.078125 | AP31: =H32-E36 -> -0.109375 | AQ31: =H32-E37 -> -0.140625 | AR31: =H32-E38 -> -0.171875 | AS31: =H32-E39 -> -0.203125 | AT31: =H32-E40 -> -0.234375 | AU31: =H32-E41 -> -0.265625 | AV31: =H32-E42 -> -0.296875 | AW31: =H32-E43 -> -0.328125 | AX31: =H32-E44 -> -0.359375 | AY31: =H32-E45 -> -0.390625 | AZ31: =H32-E46 -> -0.421875 | BA31: =H32-E47 -> -0.453125 | BB31: =H32-E48 -> -0.484375 | BC31: =H32-$E$49 -> -0.515625 | BE31: 16 | BF31: =BZ97+AO97 -> -0.03297507 | BG31: =CA97+AP97 -> -0.069020291 | BH31: =CB97+AQ97 -> -0.074141964 | BI31: =CC97+AR97 -> -0.080085553 | BJ31: =CD97+AS97 -> -0.087066441 | BK31: =CE97+AT97 -> -0.095382593 | BL31: =CF97+AU97 -> -0.10545842 | BM31: =CG97+AV97 -> -0.11791996 | ... CK31: =DE97+BT97 -> 0.06456096 | CL31: 16 | CM31: 0.00083071762 | CN31: 0.0017591604 | CO31: 0.0024923035 | CP31: 0.0032649133 | CQ31: 0.0041294222 | CR31: 0.0051405786 | CS31: 0.0063660153 | CT31: 0.0079028334 | CU31: 0.009903321 | CV31: 0.012625862 | CW31: 0.016552317 | CX31: 0.022661148 | CY31: 0.033890392 | CZ31: 0.051073238 | DA31: 0.24156648 | DB31: -0.25434977 | DC31: -0.063902052 | DD31: -0.046811725 | DE31: -0.035725087 | DF31: -0.029813944 | DG31: -0.026147678 | DH31: -0.023758516 | DI31: -0.022179932 | DJ31: -0.021175841 | DK31: -0.020627241 | DL31: -0.020488752 | DM31: -0.02077771 | DN31: -0.021591216 | DO31: -0.023167342 | DP31: -0.026191353 | DQ31: -0.031224378 | DR31: -0.069451385
B32: 16 | E32: =$B$6*B31 -> 0.46875 | F32: =($B$11/(1-$B$8)^2)*(1-2*$B$8+2*$B$8*E32-E32^2) -> 0.03548584 | G32: =($B$11/(1-$B$8)^2)*(1-2*$B$8+2*$B$8*E32-E32^2) -> 0.03548584 | H32: =(E33+E32)/2 -> 0.484375 | I32: =(E33+E32)/2 -> 0.484375 | J32: =(F33+F32)/2 -> 0.03493042 | K32: =(G33+G32)/2 -> 0.03493042 | L32: =(2*$B$8*$B$11-2*$B$11*H32)/(1-$B$8)^2 -> -0.035546875 | M32: =(2*$B$8*$B$11-2*$B$11*H32)/(1-$B$8)^2 -> -0.035546875 | O32: 16 | P32: =-2*PI()*($B$3-L32) -> -0.15025205 | Q32: =-2*PI()*($B$3-M32) -> -0.15025205 | V32: =E34-E33 -> 0.03125 | W32: =H33-E17 -> 0.515625 | X32: =H33-E18 -> 0.484375 | Y32: =H33-E19 -> 0.453125 | Z32: =H33-E20 -> 0.421875 | AA32: =H33-E21 -> 0.390625 | AB32: =H33-E22 -> 0.359375 | AC32: =H33-E23 -> 0.328125 | AD32: =H33-E24 -> 0.296875 | AE32: =H33-E25 -> 0.265625 | AF32: =H33-E26 -> 0.234375 | AG32: =H33-E27 -> 0.203125 | AH32: =H33-E28 -> 0.171875 | AI32: =H33-E29 -> 0.140625 | AJ32: =H33-E30 -> 0.109375 | AK32: =H33-E31 -> 0.078125 | AL32: =H33-E32 -> 0.046875 | AM32: =H33-E33 -> 0.015625 | AN32: =H33-E34 -> -0.015625 | AO32: =H33-E35 -> -0.046875 | AP32: =H33-E36 -> -0.078125 | AQ32: =H33-E37 -> -0.109375 | AR32: =H33-E38 -> -0.140625 | AS32: =H33-E39 -> -0.171875 | AT32: =H33-E40 -> -0.203125 | AU32: =H33-E41 -> -0.234375 | AV32: =H33-E42 -> -0.265625 | AW32: =H33-E43 -> -0.296875 | AX32: =H33-E44 -> -0.328125 | AY32: =H33-E45 -> -0.359375 | AZ32: =H33-E46 -> -0.390625 | BA32: =H33-E47 -> -0.421875 | BB32: =H33-E48 -> -0.453125 | BC32: =H33-$E$49 -> -0.484375 | BE32: 17 | BF32: =BZ98+AO98 -> -0.030934467 | BG32: =CA98+AP98 -> -0.06456096 | BH32: =CB98+AQ98 -> -0.069020291 | BI32: =CC98+AR98 -> -0.074141964 | BJ32: =CD98+AS98 -> -0.080085553 | BK32: =CE98+AT98 -> -0.087066441 | BL32: =CF98+AU98 -> -0.095382593 | BM32: =CG98+AV98 -> -0.10545842 | ... CK32: =DE98+BT98 -> 0.069020291 | CL32: 17 | CM32: 0.00072936841 | CN32: 0.0015381814 | CO32: 0.0021673741 | CP32: 0.0028212856 | CQ32: 0.0035416321 | CR32: 0.0043693362 | CS32: 0.0053517779 | CT32: 0.0065532949 | CU32: 0.008069137 | CV32: 0.010050433 | CW32: 0.01275476 | CX32: 0.01666336 | CY32: 0.022754166 | CZ32: 0.033964724 | DA32: 0.051127714 | DB32: 0.24159937 | DC32: -0.25434086 | DD32: -0.063920313 | DE32: -0.046861426 | DF32: -0.035811889 | DG32: -0.029945443 | DH32: -0.026334214 | DI32: -0.024014461 | DJ32: -0.022525822 | DK32: -0.021642052 | DL32: -0.021260756 | DM32: -0.021366548 | DN32: -0.022036368 | DO32: -0.023494774 | DP32: -0.026416228 | DQ32: -0.031352928 | DR32: -0.069403314
B33: 17 | E33: =$B$6*B32 -> 0.5 | F33: =($B$11/(1-$B$8)^2)*(1-2*$B$8+2*$B$8*E33-E33^2) -> 0.034375 | G33: =($B$11/(1-$B$8)^2)*(1-2*$B$8+2*$B$8*E33-E33^2) -> 0.034375 | H33: =(E34+E33)/2 -> 0.515625 | I33: =(E34+E33)/2 -> 0.515625 | J33: =(F34+F33)/2 -> 0.033758545 | K33: =(G34+G33)/2 -> 0.033758545 | L33: =(2*$B$8*$B$11-2*$B$11*H33)/(1-$B$8)^2 -> -0.039453125 | M33: =(2*$B$8*$B$11-2*$B$11*H33)/(1-$B$8)^2 -> -0.039453125 | O33: 17 | P33: =-2*PI()*($B$3-L33) -> -0.17479574 | Q33: =-2*PI()*($B$3-M33) -> -0.17479574 | V33: =E35-E34 -> 0.03125 | W33: =H34-E17 -> 0.546875 | X33: =H34-E18 -> 0.515625 | Y33: =H34-E19 -> 0.484375 | Z33: =H34-E20 -> 0.453125 | AA33: =H34-E21 -> 0.421875 | AB33: =H34-E22 -> 0.390625 | AC33: =H34-E23 -> 0.359375 | AD33: =H34-E24 -> 0.328125 | AE33: =H34-E25 -> 0.296875 | AF33: =H34-E26 -> 0.265625 | AG33: =H34-E27 -> 0.234375 | AH33: =H34-E28 -> 0.203125 | AI33: =H34-E29 -> 0.171875 | AJ33: =H34-E30 -> 0.140625 | AK33: =H34-E31 -> 0.109375 | AL33: =H34-E32 -> 0.078125 | AM33: =H34-E33 -> 0.046875 | AN33: =H34-E34 -> 0.015625 | AO33: =H34-E35 -> -0.015625 | AP33: =H34-E36 -> -0.046875 | AQ33: =H34-E37 -> -0.078125 | AR33: =H34-E38 -> -0.109375 | AS33: =H34-E39 -> -0.140625 | AT33: =H34-E40 -> -0.171875 | AU33: =H34-E41 -> -0.203125 | AV33: =H34-E42 -> -0.234375 | AW33: =H34-E43 -> -0.265625 | AX33: =H34-E44 -> -0.296875 | AY33: =H34-E45 -> -0.328125 | AZ33: =H34-E46 -> -0.359375 | BA33: =H34-E47 -> -0.390625 | BB33: =H34-E48 -> -0.421875 | BC33: =H34-$E$49 -> -0.453125 | BE33: 18 | BF33: =BZ99+AO99 -> -0.02913175 | BG33: =CA99+AP99 -> -0.060643217 | BH33: =CB99+AQ99 -> -0.06456096 | BI33: =CC99+AR99 -> -0.069020291 | BJ33: =CD99+AS99 -> -0.074141964 | BK33: =CE99+AT99 -> -0.080085553 | BL33: =CF99+AU99 -> -0.087066441 | BM33: =CG99+AV99 -> -0.095382593 | ... CK33: =DE99+BT99 -> 0.074141964 | CL33: 18 | CM33: 0.00064306619 | CN33: 0.0013512931 | CO33: 0.0018950517 | CP33: 0.0024534021 | CQ33: 0.003060291 | CR33: 0.0037472397 | CS33: 0.0045486449 | CT33: 0.0055089594 | CU33: 0.006690869 | CV33: 0.008188581 | CW33: 0.010152491 | CX33: 0.012839605 | CY33: 0.016730671 | CZ33: 0.02280315 | DA33: 0.033994096 | DB33: 0.05113564 | DC33: 0.24158336 | DD33: -0.25438411 | DE33: -0.063995175 | DF33: -0.046973665 | DG33: -0.035969221 | DH33: -0.030158342 | DI33: -0.026617213 | DJ33: -0.024388293 | DK33: -0.023021114 | DL33: -0.022306123 | DM33: -0.022171049 | DN33: -0.022660347 | DO33: -0.023978853 | DP33: -0.026788605 | DQ33: -0.031632246 | DR33: -0.069639036
B34: 18 | E34: =$B$6*B33 -> 0.53125 | F34: =($B$11/(1-$B$8)^2)*(1-2*$B$8+2*$B$8*E34-E34^2) -> 0.03314209 | G34: =($B$11/(1-$B$8)^2)*(1-2*$B$8+2*$B$8*E34-E34^2) -> 0.03314209 | H34: =(E35+E34)/2 -> 0.546875 | I34: =(E35+E34)/2 -> 0.546875 | J34: =(F35+F34)/2 -> 0.0324646 | K34: =(G35+G34)/2 -> 0.0324646 | L34: =(2*$B$8*$B$11-2*$B$11*H34)/(1-$B$8)^2 -> -0.043359375 | M34: =(2*$B$8*$B$11-2*$B$11*H34)/(1-$B$8)^2 -> -0.043359375 | O34: 18 | P34: =-2*PI()*($B$3-L34) -> -0.19933943 | Q34: =-2*PI()*($B$3-M34) -> -0.19933943 | V34: =E36-E35 -> 0.03125 | W34: =H35-E17 -> 0.578125 | X34: =H35-E18 -> 0.546875 | Y34: =H35-E19 -> 0.515625 | Z34: =H35-E20 -> 0.484375 | AA34: =H35-E21 -> 0.453125 | AB34: =H35-E22 -> 0.421875 | AC34: =H35-E23 -> 0.390625 | AD34: =H35-E24 -> 0.359375 | AE34: =H35-E25 -> 0.328125 | AF34: =H35-E26 -> 0.296875 | AG34: =H35-E27 -> 0.265625 | AH34: =H35-E28 -> 0.234375 | AI34: =H35-E29 -> 0.203125 | AJ34: =H35-E30 -> 0.171875 | AK34: =H35-E31 -> 0.140625 | AL34: =H35-E32 -> 0.109375 | AM34: =H35-E33 -> 0.078125 | AN34: =H35-E34 -> 0.046875 | AO34: =H35-E35 -> 0.015625 | AP34: =H35-E36 -> -0.015625 | AQ34: =H35-E37 -> -0.046875 | AR34: =H35-E38 -> -0.078125 | AS34: =H35-E39 -> -0.109375 | AT34: =H35-E40 -> -0.140625 | AU34: =H35-E41 -> -0.171875 | AV34: =H35-E42 -> -0.203125 | AW34: =H35-E43 -> -0.234375 | AX34: =H35-E44 -> -0.265625 | AY34: =H35-E45 -> -0.296875 | AZ34: =H35-E46 -> -0.328125 | BA34: =H35-E47 -> -0.359375 | BB34: =H35-E48 -> -0.390625 | BC34: =H35-$E$49 -> -0.421875 | BE34: 19 | BF34: =BZ100+AO100 -> -0.027527605 | BG34: =CA100+AP100 -> -0.057173996 | BH34: =CB100+AQ100 -> -0.060643217 | BI34: =CC100+AR100 -> -0.06456096 | BJ34: =CD100+AS100 -> -0.069020291 | BK34: =CE100+AT100 -> -0.074141964 | BL34: =CF100+AU100 -> -0.080085553 | BM34: =CG100+AV100 -> -0.087066441 | ... CK34: =DE100+BT100 -> 0.080085553 | CL34: 19 | CM34: 0.00056878088 | CN34: 0.0011913988 | CO34: 0.0016639087 | CP34: 0.0021440046 | CQ34: 0.0026598063 | CR34: 0.0032361949 | CS34: 0.0038988886 | CT34: 0.0046796729 | CU34: 0.005621519 | CV34: 0.0067861702 | CW34: 0.0082671636 | CX34: 0.010214364 | CY34: 0.012884309 | CZ34: 0.016757294 | DA34: 0.0228103 | DB34: 0.033979835 | DC34: 0.051097377 | DD34: 0.24151769 | DE34: -0.25448167 | DF34: -0.064130502 | DG34: -0.047154616 | DH34: -0.036206434 | DI34: -0.030466553 | DJ34: -0.027017412 | DK34: -0.024911453 | DL34: -0.023715041 | DM34: -0.023248987 | DN34: -0.023501311 | DO34: -0.024645268 | DP34: -0.027325899 | DQ34: -0.032074003 | DR34: -0.070167363
B35: 19 | E35: =$B$6*B34 -> 0.5625 | F35: =($B$11/(1-$B$8)^2)*(1-2*$B$8+2*$B$8*E35-E35^2) -> 0.031787109 | G35: =($B$11/(1-$B$8)^2)*(1-2*$B$8+2*$B$8*E35-E35^2) -> 0.031787109 | H35: =(E36+E35)/2 -> 0.578125 | I35: =(E36+E35)/2 -> 0.578125 | J35: =(F36+F35)/2 -> 0.031048584 | K35: =(G36+G35)/2 -> 0.031048584 | L35: =(2*$B$8*$B$11-2*$B$11*H35)/(1-$B$8)^2 -> -0.047265625 | M35: =(2*$B$8*$B$11-2*$B$11*H35)/(1-$B$8)^2 -> -0.047265625 | O35: 19 | P35: =-2*PI()*($B$3-L35) -> -0.22388313 | Q35: =-2*PI()*($B$3-M35) -> -0.22388313 | V35: =E37-E36 -> 0.03125 | W35: =H36-E17 -> 0.609375 | X35: =H36-E18 -> 0.578125 | Y35: =H36-E19 -> 0.546875 | Z35: =H36-E20 -> 0.515625 | AA35: =H36-E21 -> 0.484375 | AB35: =H36-E22 -> 0.453125 | AC35: =H36-E23 -> 0.421875 | AD35: =H36-E24 -> 0.390625 | AE35: =H36-E25 -> 0.359375 | AF35: =H36-E26 -> 0.328125 | AG35: =H36-E27 -> 0.296875 | AH35: =H36-E28 -> 0.265625 | AI35: =H36-E29 -> 0.234375 | AJ35: =H36-E30 -> 0.203125 | AK35: =H36-E31 -> 0.171875 | AL35: =H36-E32 -> 0.140625 | AM35: =H36-E33 -> 0.109375 | AN35: =H36-E34 -> 0.078125 | AO35: =H36-E35 -> 0.046875 | AP35: =H36-E36 -> 0.015625 | AQ35: =H36-E37 -> -0.015625 | AR35: =H36-E38 -> -0.046875 | AS35: =H36-E39 -> -0.078125 | AT35: =H36-E40 -> -0.109375 | AU35: =H36-E41 -> -0.140625 | AV35: =H36-E42 -> -0.171875 | AW35: =H36-E43 -> -0.203125 | AX35: =H36-E44 -> -0.234375 | AY35: =H36-E45 -> -0.265625 | AZ35: =H36-E46 -> -0.296875 | BA35: =H36-E47 -> -0.328125 | BB35: =H36-E48 -> -0.359375 | BC35: =H36-$E$49 -> -0.390625 | BE35: 20 | BF35: =BZ101+AO101 -> -0.026090931 | BG35: =CA101+AP101 -> -0.054080408 | BH35: =CB101+AQ101 -> -0.057173996 | BI35: =CC101+AR101 -> -0.060643217 | BJ35: =CD101+AS101 -> -0.06456096 | BK35: =CE101+AT101 -> -0.069020291 | BL35: =CF101+AU101 -> -0.074141964 | BM35: =CG101+AV101 -> -0.080085553 | ... CK35: =DE101+BT101 -> 0.087066441 | CL35: 20 | CM35: 0.00050420228 | CN35: 0.0010531477 | CO35: 0.0014654578 | CP35: 0.0018805009 | CQ35: 0.0023218958 | CR35: 0.0028096757 | CS35: 0.0033635457 | CT35: 0.0040068855 | CU35: 0.0047701464 | CV35: 0.0056954434 | CW35: 0.0068439029 | CX35: 0.008308565 | CY35: 0.010238849 | CZ35: 0.012890854 | DA35: 0.016744402 | DB35: 0.022775932 | DC35: 0.033921299 | DD35: 0.051011155 | DE35: 0.24139919 | DF35: -0.25463846 | DG35: -0.064333609 | DH35: -0.047414868 | DI35: -0.036538815 | DJ35: -0.030892382 | DK35: -0.027568115 | DL35: -0.025635493 | DM35: -0.024691599 | DN35: -0.024618213 | DO35: -0.025533556 | DP35: -0.028055543 | DQ35: -0.032697907 | DR35: -0.071008582
B36: 20 | E36: =$B$6*B35 -> 0.59375 | F36: =($B$11/(1-$B$8)^2)*(1-2*$B$8+2*$B$8*E36-E36^2) -> 0.030310059 | G36: =($B$11/(1-$B$8)^2)*(1-2*$B$8+2*$B$8*E36-E36^2) -> 0.030310059 | H36: =(E37+E36)/2 -> 0.609375 | I36: =(E37+E36)/2 -> 0.609375 | J36: =(F37+F36)/2 -> 0.029510498 | K36: =(G37+G36)/2 -> 0.029510498 | L36: =(2*$B$8*$B$11-2*$B$11*H36)/(1-$B$8)^2 -> -0.051171875 | M36: =(2*$B$8*$B$11-2*$B$11*H36)/(1-$B$8)^2 -> -0.051171875 | O36: 20 | P36: =-2*PI()*($B$3-L36) -> -0.24842682 | Q36: =-2*PI()*($B$3-M36) -> -0.24842682 | V36: =E38-E37 -> 0.03125 | W36: =H37-E17 -> 0.640625 | X36: =H37-E18 -> 0.609375 | Y36: =H37-E19 -> 0.578125 | Z36: =H37-E20 -> 0.546875 | AA36: =H37-E21 -> 0.515625 | AB36: =H37-E22 -> 0.484375 | AC36: =H37-E23 -> 0.453125 | AD36: =H37-E24 -> 0.421875 | AE36: =H37-E25 -> 0.390625 | AF36: =H37-E26 -> 0.359375 | AG36: =H37-E27 -> 0.328125 | AH36: =H37-E28 -> 0.296875 | AI36: =H37-E29 -> 0.265625 | AJ36: =H37-E30 -> 0.234375 | AK36: =H37-E31 -> 0.203125 | AL36: =H37-E32 -> 0.171875 | AM36: =H37-E33 -> 0.140625 | AN36: =H37-E34 -> 0.109375 | AO36: =H37-E35 -> 0.078125 | AP36: =H37-E36 -> 0.046875 | AQ36: =H37-E37 -> 0.015625 | AR36: =H37-E38 -> -0.015625 | AS36: =H37-E39 -> -0.046875 | AT36: =H37-E40 -> -0.078125 | AU36: =H37-E41 -> -0.109375 | AV36: =H37-E42 -> -0.140625 | AW36: =H37-E43 -> -0.171875 | AX36: =H37-E44 -> -0.203125 | AY36: =H37-E45 -> -0.234375 | AZ36: =H37-E46 -> -0.265625 | BA36: =H37-E47 -> -0.296875 | BB36: =H37-E48 -> -0.328125 | BC36: =H37-$E$49 -> -0.359375 | BE36: 21 | BF36: =BZ102+AO102 -> -0.024796799 | BG36: =CA102+AP102 -> -0.051304552 | BH36: =CB102+AQ102 -> -0.054080408 | BI36: =CC102+AR102 -> -0.057173996 | BJ36: =CD102+AS102 -> -0.060643217 | BK36: =CE102+AT102 -> -0.06456096 | BL36: =CF102+AU102 -> -0.069020291 | BM36: =CG102+AV102 -> -0.074141964 | ... CK36: =DE102+BT102 -> 0.095382593 | CL36: 21 | CM36: 0.00044753801 | CN36: 0.00093243038 | CO36: 0.0012932663 | CP36: 0.0016534946 | CQ36: 0.0020331655 | CR36: 0.0024486674 | CS36: 0.0029154052 | CT36: 0.0034509838 | CU36: 0.0040775773 | CV36: 0.0048248549 | CW36: 0.0057343607 | CX36: 0.0068667528 | CY36: 0.0083146444 | CZ36: 0.010227026 | DA36: 0.012859528 | DB36: 0.016691432 | DC36: 0.022698518 | DD36: 0.033815806 | DE36: 0.050872865 | DF36: 0.24122192 | DG36: -0.25486291 | DH36: -0.0646163 | DI36: -0.047771094 | DJ36: -0.036990302 | DK36: -0.031471131 | DL36: -0.028323437 | DM36: -0.0266479 | DN36: -0.026103503 | DO36: -0.026704171 | DP36: -0.029019133 | DQ36: -0.033534263 | DR36: -0.072196693
B37: 21 | E37: =$B$6*B36 -> 0.625 | F37: =($B$11/(1-$B$8)^2)*(1-2*$B$8+2*$B$8*E37-E37^2) -> 0.028710937 | G37: =($B$11/(1-$B$8)^2)*(1-2*$B$8+2*$B$8*E37-E37^2) -> 0.028710937 | H37: =(E38+E37)/2 -> 0.640625 | I37: =(E38+E37)/2 -> 0.640625 | J37: =(F38+F37)/2 -> 0.027850342 | K37: =(G38+G37)/2 -> 0.027850342 | L37: =(2*$B$8*$B$11-2*$B$11*H37)/(1-$B$8)^2 -> -0.055078125 | M37: =(2*$B$8*$B$11-2*$B$11*H37)/(1-$B$8)^2 -> -0.055078125 | O37: 21 | P37: =-2*PI()*($B$3-L37) -> -0.27297051 | Q37: =-2*PI()*($B$3-M37) -> -0.27297051 | V37: =E39-E38 -> 0.03125 | W37: =H38-E17 -> 0.671875 | X37: =H38-E18 -> 0.640625 | Y37: =H38-E19 -> 0.609375 | Z37: =H38-E20 -> 0.578125 | AA37: =H38-E21 -> 0.546875 | AB37: =H38-E22 -> 0.515625 | AC37: =H38-E23 -> 0.484375 | AD37: =H38-E24 -> 0.453125 | AE37: =H38-E25 -> 0.421875 | AF37: =H38-E26 -> 0.390625 | AG37: =H38-E27 -> 0.359375 | AH37: =H38-E28 -> 0.328125 | AI37: =H38-E29 -> 0.296875 | AJ37: =H38-E30 -> 0.265625 | AK37: =H38-E31 -> 0.234375 | AL37: =H38-E32 -> 0.203125 | AM37: =H38-E33 -> 0.171875 | AN37: =H38-E34 -> 0.140625 | AO37: =H38-E35 -> 0.109375 | AP37: =H38-E36 -> 0.078125 | AQ37: =H38-E37 -> 0.046875 | AR37: =H38-E38 -> 0.015625 | AS37: =H38-E39 -> -0.015625 | AT37: =H38-E40 -> -0.046875 | AU37: =H38-E41 -> -0.078125 | AV37: =H38-E42 -> -0.109375 | AW37: =H38-E43 -> -0.140625 | AX37: =H38-E44 -> -0.171875 | AY37: =H38-E45 -> -0.203125 | AZ37: =H38-E46 -> -0.234375 | BA37: =H38-E47 -> -0.265625 | BB37: =H38-E48 -> -0.296875 | BC37: =H38-$E$49 -> -0.328125 | BE37: 22 | BF37: =BZ103+AO103 -> -0.023624996 | BG37: =CA103+AP103 -> -0.048799852 | BH37: =CB103+AQ103 -> -0.051304552 | BI37: =CC103+AR103 -> -0.054080408 | BJ37: =CD103+AS103 -> -0.057173996 | BK37: =CE103+AT103 -> -0.060643217 | BL37: =CF103+AU103 -> -0.06456096 | BM37: =CG103+AV103 -> -0.069020291 | ... CK37: =DE103+BT103 -> 0.10545842 | CL37: 22 | CM37: 0.00039737373 | CN37: 0.00082603378 | CO37: 0.0011423654 | CP37: 0.001455828 | CQ37: 0.0017835764 | CR37: 0.0021391854 | CS37: 0.0025348977 | CT37: 0.0029842275 | CU37: 0.0035036863 | CV37: 0.0041147312 | CW37: 0.0048464995 | CX37: 0.0057400915 | CY37: 0.0068557524 | CZ37: 0.0082856736 | DA37: 0.01017838 | DB37: 0.012788958 | DC37: 0.016596021 | DD37: 0.022574503 | DE37: 0.033658319 | DF37: 0.050675545 | DG37: 0.24097635 | DH37: -0.25516808 | DI37: -0.064996732 | DJ37: -0.048249017 | DK37: -0.037598437 | DL37: -0.032259859 | DM37: -0.029374966 | DN37: -0.028107558 | DO37: -0.028251329 | DP37: -0.030279691 | DQ37: -0.034628397 | DR37: -0.073783461
B38: 22 | E38: =$B$6*B37 -> 0.65625 | F38: =($B$11/(1-$B$8)^2)*(1-2*$B$8+2*$B$8*E38-E38^2) -> 0.026989746 | G38: =($B$11/(1-$B$8)^2)*(1-2*$B$8+2*$B$8*E38-E38^2) -> 0.026989746 | H38: =(E39+E38)/2 -> 0.671875 | I38: =(E39+E38)/2 -> 0.671875 | J38: =(F39+F38)/2 -> 0.026068115 | K38: =(G39+G38)/2 -> 0.026068115 | L38: =(2*$B$8*$B$11-2*$B$11*H38)/(1-$B$8)^2 -> -0.058984375 | M38: =(2*$B$8*$B$11-2*$B$11*H38)/(1-$B$8)^2 -> -0.058984375 | O38: 22 | P38: =-2*PI()*($B$3-L38) -> -0.2975142 | Q38: =-2*PI()*($B$3-M38) -> -0.2975142 | V38: =E40-E39 -> 0.03125 | W38: =H39-E17 -> 0.703125 | X38: =H39-E18 -> 0.671875 | Y38: =H39-E19 -> 0.640625 | Z38: =H39-E20 -> 0.609375 | AA38: =H39-E21 -> 0.578125 | AB38: =H39-E22 -> 0.546875 | AC38: =H39-E23 -> 0.515625 | AD38: =H39-E24 -> 0.484375 | AE38: =H39-E25 -> 0.453125 | AF38: =H39-E26 -> 0.421875 | AG38: =H39-E27 -> 0.390625 | AH38: =H39-E28 -> 0.359375 | AI38: =H39-E29 -> 0.328125 | AJ38: =H39-E30 -> 0.296875 | AK38: =H39-E31 -> 0.265625 | AL38: =H39-E32 -> 0.234375 | AM38: =H39-E33 -> 0.203125 | AN38: =H39-E34 -> 0.171875 | AO38: =H39-E35 -> 0.140625 | AP38: =H39-E36 -> 0.109375 | AQ38: =H39-E37 -> 0.078125 | AR38: =H39-E38 -> 0.046875 | AS38: =H39-E39 -> 0.015625 | AT38: =H39-E40 -> -0.015625 | AU38: =H39-E41 -> -0.046875 | AV38: =H39-E42 -> -0.078125 | AW38: =H39-E43 -> -0.109375 | AX38: =H39-E44 -> -0.140625 | AY38: =H39-E45 -> -0.171875 | AZ38: =H39-E46 -> -0.203125 | BA38: =H39-E47 -> -0.234375 | BB38: =H39-E48 -> -0.265625 | BC38: =H39-$E$49 -> -0.296875 | BE38: 23 | BF38: =BZ104+AO104 -> -0.022558957 | BG38: =CA104+AP104 -> -0.046528412 | BH38: =CB104+AQ104 -> -0.048799852 | BI38: =CC104+AR104 -> -0.051304552 | BJ38: =CD104+AS104 -> -0.054080408 | BK38: =CE104+AT104 -> -0.057173996 | BL38: =CF104+AU104 -> -0.060643217 | BM38: =CG104+AV104 -> -0.06456096 | ... CK38: =DE104+BT104 -> 0.11791996 | CL38: 23 | CM38: 0.00035257387 | CN38: 0.00073140063 | CO38: 0.0010088445 | CP38: 0.0012819393 | CQ38: 0.0015654411 | CR38: 0.0018706999 | CS38: 0.0022075732 | CT38: 0.0025865985 | CU38: 0.0030202958 | CV38: 0.0035245159 | CW38: 0.0041202176 | CX38: 0.0048361142 | CY38: 0.0057129041 | CZ38: 0.006810415 | DA38: 0.0082203715 | DB38: 0.010090748 | DC38: 0.012675951 | DD38: 0.01645373 | DE38: 0.022397887 | DF38: 0.033440807 | DG38: 0.050408456 | DH38: 0.240648 | DI38: -0.25557381 | DJ38: -0.065502685 | DK38: -0.048888804 | DL38: -0.038423773 | DM38: -0.033355085 | DN38: -0.030889098 | DO38: -0.030327616 | DP38: -0.031934781 | DQ38: -0.036048314 | DR38: -0.075845286
